[2020-06-18 12:21:16,072] {taskinstance.py:669} INFO - Dependencies all met for <TaskInstance: slackalert.coin_flip 2020-06-18T11:19:23.659583+00:00 [queued]>
[2020-06-18 12:21:16,080] {taskinstance.py:669} INFO - Dependencies all met for <TaskInstance: slackalert.coin_flip 2020-06-18T11:19:23.659583+00:00 [queued]>
[2020-06-18 12:21:16,080] {taskinstance.py:879} INFO - 
--------------------------------------------------------------------------------
[2020-06-18 12:21:16,080] {taskinstance.py:880} INFO - Starting attempt 1 of 1
[2020-06-18 12:21:16,080] {taskinstance.py:881} INFO - 
--------------------------------------------------------------------------------
[2020-06-18 12:21:16,090] {taskinstance.py:900} INFO - Executing <Task(PythonOperator): coin_flip> on 2020-06-18T11:19:23.659583+00:00
[2020-06-18 12:21:16,091] {standard_task_runner.py:53} INFO - Started process 5534 to run task
[2020-06-18 12:21:16,148] {logging_mixin.py:112} INFO - Running %s on host %s <TaskInstance: slackalert.coin_flip 2020-06-18T11:19:23.659583+00:00 [running]> ip-172-31-76-14.ec2.internal
[2020-06-18 12:21:16,158] {taskinstance.py:1145} ERROR - Coin flipped tails. We lose!
Traceback (most recent call last):
  File "/usr/lib/python2.7/site-packages/airflow/models/taskinstance.py", line 983, in _run_raw_task
    result = task_copy.execute(context=context)
  File "/usr/lib/python2.7/site-packages/airflow/operators/python_operator.py", line 113, in execute
    return_value = self.execute_callable()
  File "/usr/lib/python2.7/site-packages/airflow/operators/python_operator.py", line 118, in execute_callable
    return self.python_callable(*self.op_args, **self.op_kwargs)
  File "/home/ec2-user/airflow/dags/slackalert.py", line 11, in coin_flip
    raise ValueError("Coin flipped tails. We lose!")
ValueError: Coin flipped tails. We lose!
[2020-06-18 12:21:16,159] {taskinstance.py:1202} INFO - Marking task as FAILED.dag_id=slackalert, task_id=coin_flip, execution_date=20200618T111923, start_date=20200618T122116, end_date=20200618T122116
[2020-06-18 12:21:16,330] {logging_mixin.py:112} INFO - [2020-06-18 12:21:16,330] {email.py:131} INFO - Sent an alert email to [u'foo@bar.com']
[2020-06-18 12:21:16,880] {taskinstance.py:1216} ERROR - Failed at executing callback
[2020-06-18 12:21:16,880] {taskinstance.py:1217} ERROR - The conn_id `snitha_slack` isn't defined
Traceback (most recent call last):
  File "/usr/lib/python2.7/site-packages/airflow/models/taskinstance.py", line 1214, in handle_failure
    task.on_failure_callback(context)
  File "/home/ec2-user/airflow/dags/slack1alert.py", line 37, in task_fail_slack_alert
    slack_webhook_token = BaseHook.get_connection(SLACK_CONN_ID).password
  File "/usr/lib/python2.7/site-packages/airflow/hooks/base_hook.py", line 84, in get_connection
    conn = random.choice(list(cls.get_connections(conn_id)))
  File "/usr/lib/python2.7/site-packages/airflow/hooks/base_hook.py", line 80, in get_connections
    return secrets.get_connections(conn_id)
  File "/usr/lib/python2.7/site-packages/airflow/secrets/__init__.py", line 56, in get_connections
    raise AirflowException("The conn_id `{0}` isn't defined".format(conn_id))
AirflowException: The conn_id `snitha_slack` isn't defined
[2020-06-18 12:21:26,067] {logging_mixin.py:112} INFO - [2020-06-18 12:21:26,066] {local_task_job.py:103} INFO - Task exited with return code 1
